Workbook

Sheet Cover
B2: EV Charging Infrastructure Design: Commercial Office Building
B3: Prepared by Anuj Kumar (B.Tech EE, DTU). Portfolio design exercise
B5: Scope
C6: 6 EV charging points (4 x 7.4 kW AC + 2 x 30 kW DC) for the parking of a 1,800 m² G+2 commercial office in Delhi.
C7: Shows the transformer impact with and without dynamic load management (DLM), an hourly DLM profile, the EV DB feeder and the final circuits.
C8: Host building data are taken from the companion project 'Electrical Design of a G+2 Commercial Office Building' (Rev 0). In that design this EV DB replaces the 2 x 7.4 kW provision on feeder F09.
C9: Change the host-building inputs and this workbook can be applied to any other building.
B11: Sheets
B12: Inputs | C12: Host building data, supply, margins, derating, charging-use assumptions
B13: Chargers | C13: Parking requirement (MoHUA bye-laws), charger schedule, phase allocation
B14: Transformer_Impact | C14: Building MD with and without DLM; DLM peak cap that keeps the 315 kVA transformer
B15: Hourly_DLM | C15: 24-hour office load profile, EV power available each hour, daily energy check, chart
B16: Cables | C16: MLTP to EV DB feeder (Al XLPE) and one final circuit per charger (Cu XLPE)
B17: Pricing | C17: AC vs DC user price (MoP 2024 tariff structure), revenue and payback
B18: Ref_Tables | C18: Havells cable data, standard breaker and transformer ratings
B20: Colour legend
B21: Blue text, yellow fill | C21: Input: edit these
B22: Black text | C22: Formula
B23: Green text | C23: Link from another sheet
B24: Green fill | C24: Key result
B26: Standards & sources
C27: IEC 61851-1 / -23 and IS 17017 (EV conductive charging); IEC 60364-7-722 (supplies for EVs); IS 732; IEC 60364-5-52
C28: MoHUA Model Building Bye-Laws 2016, amendment for EV charging infrastructure (2019): 20% of parking EV-ready
C29: Ministry of Power, Guidelines for Installation and Operation of EV Charging Infrastructure (2024): reduced solar-hour tariff 9 AM–4 PM
C30: Havells International Cables catalogue (Tables 16 and 20) for cable ampacity and resistance
B32: Limitations
C33: Parking count (30) and daily charging sessions are assumptions.
C34: DLM cap uses a unity-PF approximation for EV load; the MD checks use the full kW/kVAr sum.
C35: Office load profile is typical, not measured. Charger harmonics and RCD type must be confirmed with the charger maker.
C36: Pricing: Delhi EV tariff from the 2019 DERC order (verify current schedule); charger costs and usage are approximate assumptions.

Sheet Inputs
B2: Design inputs
B3: Parameter | C3: Value | D3: Unit | E3: Basis / note
B4: HOST BUILDING (from G+2 project, Rev 0)
B5: Non-EV feeder demand, active | C5: 166.12 | D5: kW | E5: G+2 Load_Schedule: Σ MD of all feeders except EV (F09)
B6: Non-EV feeder demand, reactive | C6: 89.03 | D6: kVAr | E6: G+2 Load_Schedule
B7: Overall diversity factor | C7: 0.9 | D7: - | E7: Same as G+2
B8: Existing transformer rating | C8: 315 | D8: kVA | E8: G+2 Sizing sheet: 11/0.433 kV, Dyn11
B9: Transformer max loading | C9: 0.8 | D9: - | E9: Same as G+2
B10: Future expansion margin | C10: 0.2 | D10: - | E10: Same as G+2
B11: LT system voltage (L-L) | C11: 415 | D11: V
B12: LT voltage (L-N) | C12: 240 | D12: V
B13: EV CHARGING USE
B14: Car parking spaces | C14: 30 | D14: nos | E14: Assumed for 1,800 m² office
B15: EV-ready share of parking | C15: 0.2 | D15: - | E15: MoHUA MBBL-2016 amendment (2019)
B16: Daily charging sessions | C16: 12 | D16: nos | E16: Assumed: 6 bays, about 2 sessions each per working day
B17: Energy per session | C17: 20 | D17: kWh | E17: Assumed average top-up
B18: Charging window start | C18: 8 | D18: h | E18: Office hours parking
B19: Charging window end | C19: 20 | D19: h | E19: Exclusive
B20: EV power factor | C20: 0.99 | D20: - | E20: Active front-end chargers
B21: CABLES
B22: Temperature derating factor | C22: 0.87 | D22: - | E22: Havells: 45°C air
B23: Grouping factor, MLTP feeder tray | C23: 0.71 | D23: - | E23: Havells: multicore touching, 2 racks x 4
B24: Grouping factor, EV final-circuit tray | C24: 0.8 | D24: - | E24: Havells: multicore touching, 1 rack x 3
B25: Voltage-drop limit | C25: 0.03 | D25: - | E25: IS 732 / IEC 60364-5-52
B26: MLTP to EV DB length | C26: 40 | D26: m | E26: Parking adjacent to building

Sheet Chargers
B1: Charger schedule
B3: A. Requirement
B4: Item | C4: Value | D4: Unit / note
B5: Charging points required | C5: =ROUNDUP(Inputs!$C$14*Inputs!$C$15,0) -> 6 | D5: parking x 20%
B6: Charging points provided | C6: =E13 -> 6 | D6: nos
B7: Check | C7: =IF(C6>=C5,"OK","Add chargers") -> OK
B9: B. Chargers
B10: Tag | C10: Charger | D10: Connector / standard | E10: Qty | F10: Output (kW) | G10: Efficiency | H10: Input each (kW) | I10: PF | J10: Phases | K10: Voltage (V) | L10: Ib each (A) | M10: Total input (kW) | N10: Total (kVA)
B11: EVC-AC | C11: AC wallbox 7.4 kW, 32 A | D11: Type 2, IEC 61851-1 / IS 17017 | E11: 4 | F11: 7.4 | G11: 0.98 | H11: =F11/G11 -> 7.5510204 | I11: =Inputs!$C$20 -> 0.99 | J11: 1 | K11: =Inputs!$C$12 -> 240 | L11: =IF(J11=1,H11*1000/(K11*I11),H11*1000/(SQRT(3)*K11*I11)) -> 31.780389 | M11: =E11*H11 -> 30.204082 | N11: =M11/I11 -> 30.509173
B12: EVC-DC | C12: DC fast charger 30 kW | D12: CCS2, IEC 61851-23 / IS 17017 | E12: 2 | F12: 30 | G12: 0.94 | H12: =F12/G12 -> 31.914894 | I12: =Inputs!$C$20 -> 0.99 | J12: 3 | K12: =Inputs!$C$11 -> 415 | L12: =IF(J12=1,H12*1000/(K12*I12),H12*1000/(SQRT(3)*K12*I12)) -> 44.848661 | M12: =E12*H12 -> 63.829787 | N12: =M12/I12 -> 64.474533
C13: Total | E13: =SUM(E11:E12) -> 6 | M13: =SUM(M11:M12) -> 94.033869 | N13: =SUM(N11:N12) -> 94.983706
B15: C. Phase allocation (connected kW)
B16: Phase | C16: AC chargers | D16: AC kW | E16: DC kW (balanced) | F16: Total kW | G16: vs average
B17: R | C17: 2 | D17: =C17*$H$11 -> 15.102041 | E17: =$M$12/3 -> 21.276596 | F17: =D17+E17 -> 36.378637 | G17: =F17/AVERAGE($F$17:$F$19)-1 -> 0.16060214
B18: Y | C18: 1 | D18: =C18*$H$11 -> 7.5510204 | E18: =$M$12/3 -> 21.276596 | F18: =D18+E18 -> 28.827616 | G18: =F18/AVERAGE($F$17:$F$19)-1 -> -0.080301071
B19: B | C19: 1 | D19: =C19*$H$11 -> 7.5510204 | E19: =$M$12/3 -> 21.276596 | F19: =D19+E19 -> 28.827616 | G19: =F19/AVERAGE($F$17:$F$19)-1 -> -0.080301071
B21: Two AC chargers share phase R (+13%). DLM allocates power phase-aware, so the R-phase pair is throttled first at peak.

Sheet Transformer_Impact
B1: Transformer impact and DLM cap
B3: Item | C3: Value | D3: Unit / formula
B4: Building MD without EV | C4: =SQRT((Inputs!$C$5*Inputs!$C$7)^2+(Inputs!$C$6*Inputs!$C$7)^2) -> 169.626 | D4: kVA
B5: Max building MD allowed on existing transformer | C5: =Inputs!$C$8*Inputs!$C$9/(1+Inputs!$C$10) -> 210 | D5: kVA = rating x 0.8 / 1.2
B6: Headroom for EV at design MD | C6: =C5-C4 -> 40.374005 | D6: kVA
B7: EV connected load | C7: =Chargers!M13 -> 94.033869 | D7: kW
B8: CASE 1, no load management: building MD | C8: =SQRT((Inputs!$C$5*Inputs!$C$7+C7)^2+(Inputs!$C$6*Inputs!$C$7+C7*TAN(ACOS(Inputs!$C$20)))^2) -> 260.88268 | D8: kVA (EV not diversified)
B9: Case 1 transformer required | C9: =C8*(1+Inputs!$C$10)/Inputs!$C$9 -> 391.32402 | D9: kVA
B10: Case 1 transformer selected | C10: =IFERROR(INDEX(Ref_Tables!$N$5:$N$14,COUNTIF(Ref_Tables!$N$5:$N$14,"<"&C9)+1),"Exceeds table") -> 400 | D10: kVA
B11: Allowable EV demand at office peak | C11: =SQRT(C5^2-(Inputs!$C$6*Inputs!$C$7)^2)-Inputs!$C$5*Inputs!$C$7 -> 44.604503 | D11: kW (EV at unity PF, approx.)
B12: CASE 2, DLM peak cap adopted | C12: =FLOOR(C11,5) -> 40 | D12: kW (rounded down to 5 kW)
B13: Case 2 building MD | C13: =SQRT((Inputs!$C$5*Inputs!$C$7+C12)^2+(Inputs!$C$6*Inputs!$C$7+C12*TAN(ACOS(Inputs!$C$20)))^2) -> 208.03726 | D13: kVA
B14: Case 2 transformer required | C14: =C13*(1+Inputs!$C$10)/Inputs!$C$9 -> 312.0559 | D14: kVA
B15: Check | C15: =IF(C14<=Inputs!$C$8,"OK: "&Inputs!$C$8&" kVA transformer retained","Upsize transformer") -> OK: 315 kVA transformer retained
B16: EV share available at peak | C16: =C12/C7 -> 0.42537865 | D16: of connected EV load
B17: Average power per charger at peak, all 6 in use | C17: =C12/Chargers!E13 -> 6.6666667 | D17: kW
B18: Transformer loading at Case 2 MD | C18: =C13/Inputs!$C$8 -> 0.66043576
B20: EV load is not diversified: under DLM it is a controlled, firm load. Without DLM the 94 kW of chargers would force a 400 kVA transformer. A 40 kW peak cap keeps building MD within 315 kVA x 0.8 / 1.2, preserving the 20% future margin.

Sheet Hourly_DLM
B1: Hourly DLM profile (typical working day)
B2: EV power available = largest EV kW that keeps building MD within the design limit (rating x 0.8 / 1.2), capped at the chargers' connected load.
B4: Hour | C4: Office load (% of MD) | D4: Building P (kW) | E4: Building Q (kVAr) | F4: EV available (kW) | G4: In charging window? | H4: EV energy in window (kWh)
B5: 0 | C5: 0.25 | D5: =Inputs!$C$5*Inputs!$C$7*C5 -> 37.377 | E5: =Inputs!$C$6*Inputs!$C$7*C5 -> 20.03175 | F5: =MAX(0,MIN(Chargers!$M$13,SQRT(Transformer_Impact!$C$5^2-E5^2)-D5)) -> 94.033869 | G5: =IF(AND(B5>=Inputs!$C$18,B5<Inputs!$C$19),"Yes","No") -> No | H5: =IF(G5="Yes",F5,0) -> 0
B6: 1 | C6: 0.25 | D6: =Inputs!$C$5*Inputs!$C$7*C6 -> 37.377 | E6: =Inputs!$C$6*Inputs!$C$7*C6 -> 20.03175 | F6: =MAX(0,MIN(Chargers!$M$13,SQRT(Transformer_Impact!$C$5^2-E6^2)-D6)) -> 94.033869 | G6: =IF(AND(B6>=Inputs!$C$18,B6<Inputs!$C$19),"Yes","No") -> No | H6: =IF(G6="Yes",F6,0) -> 0
B7: 2 | C7: 0.25 | D7: =Inputs!$C$5*Inputs!$C$7*C7 -> 37.377 | E7: =Inputs!$C$6*Inputs!$C$7*C7 -> 20.03175 | F7: =MAX(0,MIN(Chargers!$M$13,SQRT(Transformer_Impact!$C$5^2-E7^2)-D7)) -> 94.033869 | G7: =IF(AND(B7>=Inputs!$C$18,B7<Inputs!$C$19),"Yes","No") -> No | H7: =IF(G7="Yes",F7,0) -> 0
B8: 3 | C8: 0.25 | D8: =Inputs!$C$5*Inputs!$C$7*C8 -> 37.377 | E8: =Inputs!$C$6*Inputs!$C$7*C8 -> 20.03175 | F8: =MAX(0,MIN(Chargers!$M$13,SQRT(Transformer_Impact!$C$5^2-E8^2)-D8)) -> 94.033869 | G8: =IF(AND(B8>=Inputs!$C$18,B8<Inputs!$C$19),"Yes","No") -> No | H8: =IF(G8="Yes",F8,0) -> 0
B9: 4 | C9: 0.25 | D9: =Inputs!$C$5*Inputs!$C$7*C9 -> 37.377 | E9: =Inputs!$C$6*Inputs!$C$7*C9 -> 20.03175 | F9: =MAX(0,MIN(Chargers!$M$13,SQRT(Transformer_Impact!$C$5^2-E9^2)-D9)) -> 94.033869 | G9: =IF(AND(B9>=Inputs!$C$18,B9<Inputs!$C$19),"Yes","No") -> No | H9: =IF(G9="Yes",F9,0) -> 0
B10: 5 | C10: 0.25 | D10: =Inputs!$C$5*Inputs!$C$7*C10 -> 37.377 | E10: =Inputs!$C$6*Inputs!$C$7*C10 -> 20.03175 | F10: =MAX(0,MIN(Chargers!$M$13,SQRT(Transformer_Impact!$C$5^2-E10^2)-D10)) -> 94.033869 | G10: =IF(AND(B10>=Inputs!$C$18,B10<Inputs!$C$19),"Yes","No") -> No | H10: =IF(G10="Yes",F10,0) -> 0
B11: 6 | C11: 0.25 | D11: =Inputs!$C$5*Inputs!$C$7*C11 -> 37.377 | E11: =Inputs!$C$6*Inputs!$C$7*C11 -> 20.03175 | F11: =MAX(0,MIN(Chargers!$M$13,SQRT(Transformer_Impact!$C$5^2-E11^2)-D11)) -> 94.033869 | G11: =IF(AND(B11>=Inputs!$C$18,B11<Inputs!$C$19),"Yes","No") -> No | H11: =IF(G11="Yes",F11,0) -> 0
B12: 7 | C12: 0.4 | D12: =Inputs!$C$5*Inputs!$C$7*C12 -> 59.8032 | E12: =Inputs!$C$6*Inputs!$C$7*C12 -> 32.0508 | F12: =MAX(0,MIN(Chargers!$M$13,SQRT(Transformer_Impact!$C$5^2-E12^2)-D12)) -> 94.033869 | G12: =IF(AND(B12>=Inputs!$C$18,B12<Inputs!$C$19),"Yes","No") -> No | H12: =IF(G12="Yes",F12,0) -> 0
B13: 8 | C13: 0.6 | D13: =Inputs!$C$5*Inputs!$C$7*C13 -> 89.7048 | E13: =Inputs!$C$6*Inputs!$C$7*C13 -> 48.0762 | F13: =MAX(0,MIN(Chargers!$M$13,SQRT(Transformer_Impact!$C$5^2-E13^2)-D13)) -> 94.033869 | G13: =IF(AND(B13>=Inputs!$C$18,B13<Inputs!$C$19),"Yes","No") -> Yes | H13: =IF(G13="Yes",F13,0) -> 94.033869
B14: 9 | C14: 0.85 | D14: =Inputs!$C$5*Inputs!$C$7*C14 -> 127.0818 | E14: =Inputs!$C$6*Inputs!$C$7*C14 -> 68.10795 | F14: =MAX(0,MIN(Chargers!$M$13,SQRT(Transformer_Impact!$C$5^2-E14^2)-D14)) -> 71.566903 | G14: =IF(AND(B14>=Inputs!$C$18,B14<Inputs!$C$19),"Yes","No") -> Yes | H14: =IF(G14="Yes",F14,0) -> 71.566903
B15: 10 | C15: 1 | D15: =Inputs!$C$5*Inputs!$C$7*C15 -> 149.508 | E15: =Inputs!$C$6*Inputs!$C$7*C15 -> 80.127 | F15: =MAX(0,MIN(Chargers!$M$13,SQRT(Transformer_Impact!$C$5^2-E15^2)-D15)) -> 44.604503 | G15: =IF(AND(B15>=Inputs!$C$18,B15<Inputs!$C$19),"Yes","No") -> Yes | H15: =IF(G15="Yes",F15,0) -> 44.604503
B16: 11 | C16: 1 | D16: =Inputs!$C$5*Inputs!$C$7*C16 -> 149.508 | E16: =Inputs!$C$6*Inputs!$C$7*C16 -> 80.127 | F16: =MAX(0,MIN(Chargers!$M$13,SQRT(Transformer_Impact!$C$5^2-E16^2)-D16)) -> 44.604503 | G16: =IF(AND(B16>=Inputs!$C$18,B16<Inputs!$C$19),"Yes","No") -> Yes | H16: =IF(G16="Yes",F16,0) -> 44.604503
... B28: 23 | C28: 0.25 | D28: =Inputs!$C$5*Inputs!$C$7*C28 -> 37.377 | E28: =Inputs!$C$6*Inputs!$C$7*C28 -> 20.03175 | F28: =MAX(0,MIN(Chargers!$M$13,SQRT(Transformer_Impact!$C$5^2-E28^2)-D28)) -> 94.033869 | G28: =IF(AND(B28>=Inputs!$C$18,B28<Inputs!$C$19),"Yes","No") -> No | H28: =IF(G28="Yes",F28,0) -> 0
B30: Daily EV energy deliverable in window | H30: =SUM(H5:H28) -> 728.57246
B31: Daily EV energy needed (sessions x kWh) | H31: =Inputs!$C$16*Inputs!$C$17 -> 240
B32: Check | H32: =IF(H30>=H31,"OK: "&TEXT(H30/H31,"0.0")&"x the daily need","Short") -> OK: 3.0x the daily need
B33: Lowest EV power in window (sets the DLM cap) | H33: =MIN(F14:F21) -> 44.604503

Sheet Cables
B1: Cable schedule: EV DB feeder and final circuits
B3: A. MLTP to EV DB feeder (Al XLPE, sized on full connected load: no DLM credit)
B4: Tag | C4: From | D4: To | E4: Load (kVA) | F4: Ib (A) | G4: Breaker In (A) | H4: Iz needed (A) | I4: Size (mm²) | J4: Iz derated (A) | K4: ΔV (%) | L4: Check | M4: Cable
B5: F09 | C5: Main LT Panel | D5: EV Charger DB | E5: =Chargers!N13 -> 94.983706 | F5: =E5*1000/(SQRT(3)*Inputs!$C$11) -> 132.14185 | G5: =IFERROR(INDEX(Ref_Tables!$L$5:$L$21,COUNTIF(Ref_Tables!$L$5:$L$21,"<"&F5)+1),"Exceeds table") -> 160 | H5: =G5/(Inputs!$C$22*Inputs!$C$23) -> 259.02542 | I5: =INDEX(Ref_Tables!$B$5:$B$14,MAX(COUNTIF(Ref_Tables!$C$5:$C$14,"<"&H5)+1,COUNTIF(Ref_Tables!$E$5:$E$14,">"&(Inputs!$C$25*Inputs!$C$11*1000/(F5*Inputs!$C$26)))+1)) -> 120 | J5: =INDEX(Ref_Tables!$C$5:$C$14,MATCH(I5,Ref_Tables!$B$5:$B$14,0))*Inputs!$C$22*Inputs!$C$23 -> 162.4551 | K5: =INDEX(Ref_Tables!$E$5:$E$14,MATCH(I5,Ref_Tables!$B$5:$B$14,0))*F5*Inputs!$C$26/(1000*Inputs!$C$11) -> 0.0073546044 | L5: =IF(AND(J5>=G5,K5<=Inputs!$C$25),"OK","CHECK") -> OK | M5: ="1R x 3.5C x "&I5&" sq.mm Al XLPE armd, "&Inputs!$C$26&" m" -> 1R x 3.5C x 120 sq.mm Al XLPE armd, 40 m
B7: B. Final circuits, one per charger (Cu XLPE). In ≥ 1.25 x Ib (charging is a continuous load)
B8: Circuit | C8: Charger | D8: Phase | E8: Ib (A) | F8: Breaker In (A) | G8: RCD | H8: Iz needed (A) | I8: Size Cu (mm²) | J8: Length (m) | K8: ΔV (%) | L8: Check
B9: EV-1 | C9: EVC-AC | D9: R | E9: =Chargers!L11 -> 31.780389 | F9: =IFERROR(INDEX(Ref_Tables!$L$5:$L$21,COUNTIF(Ref_Tables!$L$5:$L$21,"<"&E9*1.25)+1),"Exceeds table") -> 40 | G9: 30 mA Type A + 6 mA DC detection (in charger) | H9: =F9/(Inputs!$C$22*Inputs!$C$24) -> 57.471264 | I9: =IFERROR(INDEX(Ref_Tables!$G$5:$G$10,COUNTIF(Ref_Tables!$H$5:$H$10,"<"&H9)+1),"Too big") -> 10 | J9: 25 | K9: =IF(ISNUMBER(I9),IF(Chargers!J11=1,2,SQRT(3))*INDEX(Ref_Tables!$J$5:$J$10,MATCH(I9,Ref_Tables!$G$5:$G$10,0))*E9*J9/(1000*Chargers!K11),0) -> 0.01544946 | L9: =IF(AND(ISNUMBER(I9),K9<=Inputs!$C$25),"OK","CHECK") -> OK
B10: EV-2 | C10: EVC-AC | D10: Y | E10: =Chargers!L11 -> 31.780389 | F10: =IFERROR(INDEX(Ref_Tables!$L$5:$L$21,COUNTIF(Ref_Tables!$L$5:$L$21,"<"&E10*1.25)+1),"Exceeds table") -> 40 | G10: 30 mA Type A + 6 mA DC detection (in charger) | H10: =F10/(Inputs!$C$22*Inputs!$C$24) -> 57.471264 | I10: =IFERROR(INDEX(Ref_Tables!$G$5:$G$10,COUNTIF(Ref_Tables!$H$5:$H$10,"<"&H10)+1),"Too big") -> 10 | J10: 30 | K10: =IF(ISNUMBER(I10),IF(Chargers!J11=1,2,SQRT(3))*INDEX(Ref_Tables!$J$5:$J$10,MATCH(I10,Ref_Tables!$G$5:$G$10,0))*E10*J10/(1000*Chargers!K11),0) -> 0.018539352 | L10: =IF(AND(ISNUMBER(I10),K10<=Inputs!$C$25),"OK","CHECK") -> OK
B11: EV-3 | C11: EVC-AC | D11: B | E11: =Chargers!L11 -> 31.780389 | F11: =IFERROR(INDEX(Ref_Tables!$L$5:$L$21,COUNTIF(Ref_Tables!$L$5:$L$21,"<"&E11*1.25)+1),"Exceeds table") -> 40 | G11: 30 mA Type A + 6 mA DC detection (in charger) | H11: =F11/(Inputs!$C$22*Inputs!$C$24) -> 57.471264 | I11: =IFERROR(INDEX(Ref_Tables!$G$5:$G$10,COUNTIF(Ref_Tables!$H$5:$H$10,"<"&H11)+1),"Too big") -> 10 | J11: 35 | K11: =IF(ISNUMBER(I11),IF(Chargers!J11=1,2,SQRT(3))*INDEX(Ref_Tables!$J$5:$J$10,MATCH(I11,Ref_Tables!$G$5:$G$10,0))*E11*J11/(1000*Chargers!K11),0) -> 0.021629244 | L11: =IF(AND(ISNUMBER(I11),K11<=Inputs!$C$25),"OK","CHECK") -> OK
B12: EV-4 | C12: EVC-AC | D12: R | E12: =Chargers!L11 -> 31.780389 | F12: =IFERROR(INDEX(Ref_Tables!$L$5:$L$21,COUNTIF(Ref_Tables!$L$5:$L$21,"<"&E12*1.25)+1),"Exceeds table") -> 40 | G12: 30 mA Type A + 6 mA DC detection (in charger) | H12: =F12/(Inputs!$C$22*Inputs!$C$24) -> 57.471264 | I12: =IFERROR(INDEX(Ref_Tables!$G$5:$G$10,COUNTIF(Ref_Tables!$H$5:$H$10,"<"&H12)+1),"Too big") -> 10 | J12: 40 | K12: =IF(ISNUMBER(I12),IF(Chargers!J11=1,2,SQRT(3))*INDEX(Ref_Tables!$J$5:$J$10,MATCH(I12,Ref_Tables!$G$5:$G$10,0))*E12*J12/(1000*Chargers!K11),0) -> 0.024719136 | L12: =IF(AND(ISNUMBER(I12),K12<=Inputs!$C$25),"OK","CHECK") -> OK
B13: EV-5 | C13: EVC-DC | D13: RYB | E13: =Chargers!L12 -> 44.848661 | F13: =IFERROR(INDEX(Ref_Tables!$L$5:$L$21,COUNTIF(Ref_Tables!$L$5:$L$21,"<"&E13*1.25)+1),"Exceeds table") -> 63 | G13: 30 mA Type B (unless charger isolated) | H13: =F13/(Inputs!$C$22*Inputs!$C$24) -> 90.517241 | I13: =IFERROR(INDEX(Ref_Tables!$G$5:$G$10,COUNTIF(Ref_Tables!$H$5:$H$10,"<"&H13)+1),"Too big") -> 25 | J13: 20 | K13: =IF(ISNUMBER(I13),IF(Chargers!J12=1,2,SQRT(3))*INDEX(Ref_Tables!$J$5:$J$10,MATCH(I13,Ref_Tables!$G$5:$G$10,0))*E13*J13/(1000*Chargers!K12),0) -> 0.0034703291 | L13: =IF(AND(ISNUMBER(I13),K13<=Inputs!$C$25),"OK","CHECK") -> OK
B14: EV-6 | C14: EVC-DC | D14: RYB | E14: =Chargers!L12 -> 44.848661 | F14: =IFERROR(INDEX(Ref_Tables!$L$5:$L$21,COUNTIF(Ref_Tables!$L$5:$L$21,"<"&E14*1.25)+1),"Exceeds table") -> 63 | G14: 30 mA Type B (unless charger isolated) | H14: =F14/(Inputs!$C$22*Inputs!$C$24) -> 90.517241 | I14: =IFERROR(INDEX(Ref_Tables!$G$5:$G$10,COUNTIF(Ref_Tables!$H$5:$H$10,"<"&H14)+1),"Too big") -> 25 | J14: 25 | K14: =IF(ISNUMBER(I14),IF(Chargers!J12=1,2,SQRT(3))*INDEX(Ref_Tables!$J$5:$J$10,MATCH(I14,Ref_Tables!$G$5:$G$10,0))*E14*J14/(1000*Chargers!K12),0) -> 0.0043379114 | L14: =IF(AND(ISNUMBER(I14),K14<=Inputs!$C$25),"OK","CHECK") -> OK
B16: ΔV single-phase = 2·Z·I·L; three-phase = √3·Z·I·L. Each charger has its own circuit, RCD and protective earth (IEC 60364-7-722). EV DB is not on the DG bus.

Sheet Pricing
B1: Charging price, revenue and payback (AC vs DC)
B2: EV DB separately sub-metered behind the building's HT connection (permitted by MoP 2024): single-part EV tariff, no demand charge. DC premium comes from the higher service-charge ceiling.
B4: A. Tariff and charge inputs
B5: Item | C5: AC | D5: DC | E5: Basis / source
B6: Base EV energy tariff (₹/kWh) | C6: 4.5 | D6: 4.5 | E6: DERC EV tariff, LT (₹4.5/kWh, 2019 order). Verify current DISCOM schedule
B7: Solar-hour multiplier (9 AM–4 PM) | C7: 0.7 | D7: 0.7 | E7: MoP EV Charging Guidelines 2024: 0.7 x in solar hours
B8: Non-solar-hour multiplier | C8: 1.3 | D8: 1.3 | E8: MoP 2024: 1.3 x in non-solar hours
B9: Service charge, solar hours (₹/kWh) | C9: 3 | D9: 11 | E9: MoP 2024 ceiling: AC ₹3, DC ₹11 (valid to Mar 2028)
B10: Service charge, non-solar hours (₹/kWh) | C10: 4 | D10: 13 | E10: MoP 2024 ceiling: AC ₹4, DC ₹13
B11: GST on charging service | C11: 0.18 | D11: 0.18 | E11: 18% on the charging service
B12: Charger efficiency (input energy / delivered) | C12: =Chargers!G11 -> 0.98 | D12: =Chargers!G12 -> 0.94 | E12: From Chargers sheet: operator buys input energy
B13: Share of energy delivered in solar hours | C13: 0.6 | D13: 0.4 | E13: Assumed: AC = long-dwell staff cars in office hours; DC = more early/late top-ups (DLM limits EV power 10 AM–5 PM)
B14: Sessions per working day | C14: 6 | D14: 6 | E14: Assumed: 12 total, as on Inputs sheet
B15: Energy per session (kWh) | C15: 20 | D15: 20 | E15: Assumed, as on Inputs sheet
B16: Working days per year | C16: 300 | D16: 300 | E16: Assumed
B17: Idle fee after 15-min grace (₹/min) | C17: 0 | D17: 5 | E17: DC bays only, to free the fast charger. Not counted in revenue
B19: B. Price to the EV user (₹/kWh, incl. GST)
B20: Item | C20: AC | D20: DC | E20: Formula
B21: Energy pass-through, solar hours | C21: =C6*C7/C12 -> 3.2142857 | D21: =D6*D7/D12 -> 3.3510638 | E21: tariff x multiplier / efficiency
B22: Energy pass-through, non-solar hours | C22: =C6*C8/C12 -> 5.9693878 | D22: =D6*D8/D12 -> 6.2234043
B23: User price, solar hours | C23: =(C21+C9)*(1+C11) -> 7.3328571 | D23: =(D21+D9)*(1+D11) -> 16.934255 | E23: (energy + service) x 1.18
B24: User price, non-solar hours | C24: =(C22+C10)*(1+C11) -> 11.763878 | D24: =(D22+D10)*(1+D11) -> 22.683617
B25: Weighted average user price | C25: =C13*C23+(1-C13)*C24 -> 9.1052653 | D25: =D13*D23+(1-D13)*D24 -> 20.383872 | E25: by solar-hour share
B26: Cost of a 20 kWh session, solar hours | C26: =C23*C15 -> 146.65714 | D26: =D23*D15 -> 338.68511 | E26: ₹
B27: Cost of a 20 kWh session, non-solar hours | C27: =C24*C15 -> 235.27755 | D27: =D24*D15 -> 453.67234 | E27: ₹
B28: Time for a 20 kWh session (h) | C28: =C15/Chargers!F11 -> 2.7027027 | D28: =D15/Chargers!F12 -> 0.66666667 | E28: at full charger power
B29: DC premium over AC (weighted price) | D29: =D25/C25-1 -> 1.2386907 | E29: what the user pays for speed
B31: C. Revenue and payback (operator view)
B32: Item | C32: AC | D32: DC | E32: Basis
B33: Number of chargers | C33: =Chargers!E11 -> 4 | D33: =Chargers!E12 -> 2
B34: Energy delivered per year (kWh) | C34: =C14*C15*C16 -> 36000 | D34: =D14*D15*D16 -> 36000 | E34: sessions x kWh x days
B35: Service revenue per year (₹, ex-GST) | C35: =C34*(C13*C9+(1-C13)*C10) -> 122400 | D35: =D34*(D13*D9+(1-D13)*D10) -> 439200 | E35: energy is a pass-through; margin = service charge
B36: Charger cost, installed (₹ each) | C36: 70000 | D36: 700000 | E36: Approx. market: 7.4 kW wallbox ~₹0.5–0.8 L; 30 kW DC ~₹6–8 L. Replace with quotes
B37: Share of EV DB, feeder and civil works (₹) | C37: 100000 | D37: 200000 | E37: Approx. total ₹3 L split 1:2 (DC bays need more)
B38: Total capex (₹) | C38: =C33*C36+C37 -> 380000 | D38: =D33*D36+D37 -> 1600000
B39: O&M per year (% of capex) | C39: 0.04 | D39: 0.04 | E39: Assumed
B40: Charge-management software (₹ per charger per month) | C40: 500 | D40: 500 | E40: Assumed CMS / OCPP backend fee
B41: Operating cost per year (₹) | C41: =C38*C39+C33*C40*12 -> 39200 | D41: =D38*D39+D33*D40*12 -> 76000
B42: Net margin per year (₹) | C42: =C35-C41 -> 83200 | D42: =D35-D41 -> 363200
B43: Simple payback (years) | C43: =IF(C42>0,C38/C42,"No payback") -> 4.5673077 | D43: =IF(D42>0,D38/D42,"No payback") -> 4.4052863 | E43: capex / net margin
...

Sheet Ref_Tables
B2: Reference tables
B3: Al 3.5C/4C XLPE armd, air 30°C (Havells T16/T20) | G3: Cu 4C XLPE armd, air 30°C (Havells T20)
B4: Size (mm²) | C4: Ampacity (A) | D4: R @20°C (Ω/km) | E4: mV/A/m 3-ph | G4: Size (mm²) | H4: Ampacity (A) | I4: R @20°C (Ω/km) | J4: Z @90°C (Ω/km) | L4: Breaker In (A) | N4: Transformer (kVA)
B5: 16 | C5: 77 | D5: 1.91 | E5: =SQRT(3)*SQRT((D5*(1+0.00403*70))^2+0.077^2) -> 4.2435614 | G5: 4 | H5: 39 | I5: 4.61 | J5: =I5*(1+0.00393*70) -> 5.878211 | L5: 16 | N5: 100
B6: 25 | C6: 97 | D6: 1.2 | E6: =SQRT(3)*SQRT((D6*(1+0.00403*70))^2+0.077^2) -> 2.6681301 | G6: 6 | H6: 49 | I6: 3.08 | J6: =I6*(1+0.00393*70) -> 3.927308 | L6: 20 | N6: 160
B7: 35 | C7: 120 | D7: 0.868 | E7: =SQRT(3)*SQRT((D7*(1+0.00403*70))^2+0.077^2) -> 1.9321433 | G7: 10 | H7: 65 | I7: 1.83 | J7: =I7*(1+0.00393*70) -> 2.333433 | L7: 25 | N7: 200
B8: 50 | C8: 146 | D8: 0.641 | E8: =SQRT(3)*SQRT((D8*(1+0.00403*70))^2+0.077^2) -> 1.4296788 | G8: 16 | H8: 84 | I8: 1.15 | J8: =I8*(1+0.00393*70) -> 1.466365 | L8: 32 | N8: 250
B9: 70 | C9: 187 | D9: 0.443 | E9: =SQRT(3)*SQRT((D9*(1+0.00403*70))^2+0.077^2) -> 0.99275263 | G9: 25 | H9: 107 | I9: 0.727 | J9: =I9*(1+0.00393*70) -> 0.9269977 | L9: 40 | N9: 315
B10: 95 | C10: 227 | D10: 0.32 | E10: =SQRT(3)*SQRT((D10*(1+0.00403*70))^2+0.077^2) -> 0.72301891 | G10: 35 | H10: 129 | I10: 0.524 | J10: =I10*(1+0.00393*70) -> 0.6681524 | L10: 50 | N10: 400
B11: 120 | C11: 263 | D11: 0.253 | E11: =SQRT(3)*SQRT((D11*(1+0.00403*70))^2+0.077^2) -> 0.57744023 | L11: 63 | N11: 500
B12: 150 | C12: 304 | D12: 0.206 | E12: =SQRT(3)*SQRT((D12*(1+0.00403*70))^2+0.077^2) -> 0.4765012 | L12: 80 | N12: 630
B13: 185 | C13: 347 | D13: 0.164 | E13: =SQRT(3)*SQRT((D13*(1+0.00403*70))^2+0.077^2) -> 0.38784063 | L13: 100 | N13: 800
B14: 240 | C14: 409 | D14: 0.125 | E14: =SQRT(3)*SQRT((D14*(1+0.00403*70))^2+0.077^2) -> 0.30795975 | L14: 125 | N14: 1000
L15: 160
L16: 200
L17: 250
L18: 320
L19: 400
L20: 500
L21: 630
